<?xml version="1.0" ?>
<!-- =================================================================================== -->
<!-- |    This document was autogenerated by xacro from sda10f_uni_kin_ref_kin_macro_newKin.xacro | -->
<!-- |    EDITING THIS FILE BY HAND IS NOT RECOMMENDED                                 | -->
<!-- =================================================================================== -->
<robot name="sda10f" xmlns:xacro="http://ros.org/wiki/xacro">
  <!--    <xacro:include filename="$(find reflex_visualizer)/urdf/rhr_reflex_macro.xacro" /> -->
  <link name="base_uni">
    <visual>
      <geometry>
        <mesh filename="package://motoman_sda10f_support/meshes/sda10f/visual/unigripper_v2_body1.stl"/>
      </geometry>
      <material name="silver">
        <color rgba="0.76 0.76 0.82 1"/>
      </material>
    </visual>
    <collision>
      <origin rpy="0 0 0" xyz="0 0 0"/>
      <geometry>
        <mesh filename="package://motoman_sda10f_support/meshes/sda10f/visual/unigripper_v2_body1.stl"/>
      </geometry>
      <material name="silver">
        <color rgba="0.76 0.76 0.82 1"/>
      </material>
    </collision>
    <inertial>
      <origin rpy="0 0 0" xyz="0 0 0"/>
      <mass value="0.0"/>
      <inertia ixx="0" ixy="0" ixz="0" iyy="0" iyz="0" izz="0"/>
    </inertial>
  </link>
  <link name="left_movable_pipe">
    <visual>
      <geometry>
        <cylinder length="0.092" radius="0.006"/>
      </geometry>
      <material name="light_black">
        <color rgba="0.1 0.1 0.1 1"/>
      </material>
    </visual>
    <collision>
      <origin rpy="0 0 0" xyz="0 0 0"/>
      <geometry>
        <cylinder length="0.092" radius="0.006"/>
      </geometry>
      <material name="light_black">
        <color rgba="0.1 0.1 0.1 1"/>
      </material>
    </collision>
    <inertial>
      <origin rpy="0 0 0" xyz="0 0 0"/>
      <mass value="0.0"/>
      <inertia ixx="0" ixy="0" ixz="0" iyy="0" iyz="0" izz="0"/>
    </inertial>
  </link>
  <link name="parallel_gripper">
    <visual>
      <geometry>
        <!-- <box size="0.055 .025 .11"/> -->
        <box size="0.05 .02 .05"/>
      </geometry>
      <material name="green">
        <color rgba="0.05 0.85 0.05 0.5"/>
      </material>
    </visual>
    <collision>
      <geometry>
        <box size="0.055 .025 .05"/>
      </geometry>
      <material name="green">
        <color rgba="0.05 0.85 0.05 0.5"/>
      </material>
    </collision>
    <inertial>
      <origin rpy="0 0 0" xyz="0 0 0"/>
      <mass value="0.0"/>
      <inertia ixx="0" ixy="0" ixz="0" iyy="0" iyz="0" izz="0"/>
    </inertial>
  </link>
  <link name="right_movable_pipe">
    <visual>
      <geometry>
        <cylinder length="0.104" radius="0.006"/>
      </geometry>
      <material name="light_black">
        <color rgba="0.1 0.1 0.1 1"/>
      </material>
    </visual>
    <collision>
      <origin rpy="0 0 0" xyz="0 0 0"/>
      <geometry>
        <cylinder length="0.104" radius="0.006"/>
      </geometry>
      <material name="light_black">
        <color rgba="0.1 0.1 0.1 1"/>
      </material>
    </collision>
    <inertial>
      <origin rpy="0 0 0" xyz="0 0 0"/>
      <mass value="0.0"/>
      <inertia ixx="0" ixy="0" ixz="0" iyy="0" iyz="0" izz="0"/>
    </inertial>
  </link>
  <link name="passive_finger">
    <visual>
      <geometry>
        <mesh filename="package://motoman_sda10f_support/meshes/sda10f/visual/unigripper_v2_passive_finger1.stl"/>
      </geometry>
      <material name="silver">
        <color rgba="0.76 0.76 0.82 1"/>
      </material>
    </visual>
    <collision>
      <origin rpy="0 0 0" xyz="0 0 0"/>
      <geometry>
        <mesh filename="package://motoman_sda10f_support/meshes/sda10f/visual/unigripper_v2_passive_finger1.stl"/>
      </geometry>
      <material name="silver">
        <color rgba="0.76 0.76 0.82 1"/>
      </material>
    </collision>
    <inertial>
      <origin rpy="0 0 0" xyz="0 0 0"/>
      <mass value="0.0"/>
      <inertia ixx="0" ixy="0" ixz="0" iyy="0" iyz="0" izz="0"/>
    </inertial>
  </link>
  <link name="vacuum_finger">
    <visual>
      <geometry>
        <mesh filename="package://motoman_sda10f_support/meshes/sda10f/visual/unigripper_v2_vacuum_finger7.stl"/>
      </geometry>
      <material name="silver">
        <color rgba="0.76 0.76 0.82 1"/>
      </material>
    </visual>
    <collision>
      <origin rpy="0 0 0" xyz="0 0 0"/>
      <geometry>
        <mesh filename="package://motoman_sda10f_support/meshes/sda10f/visual/unigripper_v2_vacuum_finger7.stl"/>
      </geometry>
      <material name="silver">
        <color rgba="0.76 0.76 0.82 1"/>
      </material>
    </collision>
    <inertial>
      <origin rpy="0 0 0" xyz="0 0 0"/>
      <mass value="0.0"/>
      <inertia ixx="0" ixy="0" ixz="0" iyy="0" iyz="0" izz="0"/>
    </inertial>
  </link>
  <link name="upper_jaw">
    <visual>
      <geometry>
        <box size="0.294 0.035 0.028"/>
      </geometry>
      <material name="silver">
        <color rgba="0.76 0.76 0.82 1"/>
      </material>
    </visual>
    <collision>
      <origin rpy="0 0 0" xyz="0 0 0"/>
      <geometry>
        <box size="0.294 0.035 0.028"/>
      </geometry>
      <material name="silver">
        <color rgba="0.76 0.76 0.82 1"/>
      </material>
    </collision>
    <inertial>
      <origin rpy="0 0 0" xyz="0 0 0"/>
      <mass value="0.0"/>
      <inertia ixx="0" ixy="0" ixz="0" iyy="0" iyz="0" izz="0"/>
    </inertial>
  </link>
  <link name="air_feed_plate">
    <visual>
      <geometry>
        <mesh filename="package://motoman_sda10f_support/meshes/sda10f/visual/air_feed_plate.stl"/>
      </geometry>
      <material name="red">
        <color rgba="1 0 0 1"/>
      </material>
    </visual>
    <collision>
      <origin rpy="0 0 0" xyz="0 0 0"/>
      <geometry>
        <mesh filename="package://motoman_sda10f_support/meshes/sda10f/visual/air_feed_plate.stl"/>
      </geometry>
      <material name="red">
        <color rgba="1 0 0 1"/>
      </material>
    </collision>
    <inertial>
      <origin rpy="0 0 0" xyz="0 0 0"/>
      <mass value="0.0"/>
      <inertia ixx="0" ixy="0" ixz="0" iyy="0" iyz="0" izz="0"/>
    </inertial>
  </link>
  <link name="upper_vacuum">
    <visual>
      <geometry>
        <box size="0.095 0.035 0.011"/>
      </geometry>
      <material name="dark_grey">
        <color rgba="0.2 0.2 0.2 1"/>
      </material>
    </visual>
    <collision>
      <origin rpy="0 0 0" xyz="0 0 0"/>
      <geometry>
        <box size="0.095 0.035 0.011"/>
      </geometry>
      <material name="dark_grey">
        <color rgba="0.2 0.2 0.2 1"/>
      </material>
    </collision>
    <inertial>
      <origin rpy="0 0 0" xyz="0 0 0"/>
      <mass value="0.0"/>
      <inertia ixx="0" ixy="0" ixz="0" iyy="0" iyz="0" izz="0"/>
    </inertial>
  </link>
  <link name="sponge_upper_jaw">
    <visual>
      <geometry>
        <box size="0.132 0.035 0.005"/>
      </geometry>
      <material name="dark_grey">
        <color rgba="0.2 0.2 0.2 1"/>
      </material>
    </visual>
    <collision>
      <origin rpy="0 0 0" xyz="0 0 0"/>
      <geometry>
        <box size="0.132 0.035 0.005"/>
      </geometry>
      <material name="dark_grey">
        <color rgba="0.2 0.2 0.2 1"/>
      </material>
    </collision>
    <inertial>
      <origin rpy="0 0 0" xyz="0 0 0"/>
      <mass value="0.0"/>
      <inertia ixx="0" ixy="0" ixz="0" iyy="0" iyz="0" izz="0"/>
    </inertial>
  </link>
  <link name="vacuum_base">
    <visual>
      <geometry>
        <box size="0.005 0.035 0.028"/>
      </geometry>
      <material name="dark_grey">
        <color rgba="0.2 0.2 0.2 1"/>
      </material>
    </visual>
    <collision>
      <origin rpy="0 0 0" xyz="0 0 0"/>
      <geometry>
        <box size="0.005 0.035 0.028"/>
      </geometry>
      <material name="dark_grey">
        <color rgba="0.2 0.2 0.2 1"/>
      </material>
    </collision>
    <inertial>
      <origin rpy="0 0 0" xyz="0 0 0"/>
      <mass value="0.0"/>
      <inertia ixx="0" ixy="0" ixz="0" iyy="0" iyz="0" izz="0"/>
    </inertial>
  </link>
  <link name="pre_front_vacuum">
    <visual>
      <geometry>
        <cylinder length="0.02" radius="0.0095"/>
      </geometry>
      <material name="gold">
        <color rgba="0.5 0.5 0.0 1"/>
      </material>
    </visual>
    <collision>
      <origin rpy="0 0 0" xyz="0 0 0"/>
      <geometry>
        <cylinder length="0.05" radius="0.0095"/>
      </geometry>
      <material name="gold">
        <color rgba="0.5 0.5 0.0 1"/>
      </material>
    </collision>
    <inertial>
      <origin rpy="0 0 0" xyz="0 0 0"/>
      <mass value="0.0"/>
      <inertia ixx="0" ixy="0" ixz="0" iyy="0" iyz="0" izz="0"/>
    </inertial>
  </link>
  <link name="front_vacuum">
    <visual>
      <geometry>
        <cylinder length="0.02" radius="0.019"/>
      </geometry>
      <material name="gold">
        <color rgba="0.5 0.5 0.0 1"/>
      </material>
    </visual>
    <collision>
      <origin rpy="0 0 0" xyz="0 0 0"/>
      <geometry>
        <cylinder length="0.02" radius="0.019"/>
      </geometry>
      <material name="gold">
        <color rgba="0.5 0.5 0.0 1"/>
      </material>
    </collision>
    <inertial>
      <origin rpy="0 0 0" xyz="0 0 0"/>
      <mass value="0.0"/>
      <inertia ixx="0" ixy="0" ixz="0" iyy="0" iyz="0" izz="0"/>
    </inertial>
  </link>
  <!-- JOINTS -->
  <joint name="joint_right_movable_pipe" type="prismatic">
    <parent link="base_uni"/>
    <child link="right_movable_pipe"/>
    <axis xyz="0 0 -1"/>
    <limit effort="50" lower="0.003" upper="0.052" velocity="0.2"/>
    <!-- <origin xyz="0.0055 0.0225 -0.1005" rpy="0 0 0" /> -->
    <origin rpy="0 1.5707 0" xyz="0.075 -0.015 0.0203"/>
  </joint>
  <joint name="joint_left_movable_pipe" type="prismatic">
    <parent link="base_uni"/>
    <child link="left_movable_pipe"/>
    <axis xyz="0 0 1"/>
    <limit effort="50" lower="0.0" upper="0.046" velocity="0.2"/>
    <!-- <origin xyz="0.0055 0.0225 -0.1005" rpy="0 0 0" /> -->
    <origin rpy="0 1.5707 0" xyz="-0.075 0.027 0.0203"/>
  </joint>
  <joint name="joint_parallel_gripper" type="fixed">
    <!-- <origin rpy="0 0 0" xyz="-0.0125 0.01 0.28"/> -->
    <origin rpy="0 0 0" xyz="0.0 0.0 0.31"/>
    <axis xyz="0 0 0"/>
    <parent link="base_uni"/>
    <child link="parallel_gripper"/>
  </joint>
  <joint name="joint_passive_finger" type="fixed">
    <origin rpy="0 -1.5707 0" xyz="-0.150849 0.0065 -0.0003"/>
    <axis xyz="0 0 0"/>
    <parent link="right_movable_pipe"/>
    <child link="passive_finger"/>
  </joint>
  <joint name="joint_vacuum_finger" type="fixed">
    <origin rpy="0 -1.5707 0" xyz="-0.024 0.01 0.0063"/>
    <axis xyz="0 0 0"/>
    <parent link="left_movable_pipe"/>
    <child link="vacuum_finger"/>
  </joint>
  <joint name="joint_upper_jaw" type="fixed">
    <origin rpy="0 1.5707 0" xyz="-0.0105 -0.0315 0.1505"/>
    <axis xyz="0 0 0"/>
    <parent link="vacuum_finger"/>
    <child link="upper_jaw"/>
  </joint>
  <joint name="joint_air_feed_plate" type="fixed">
    <origin rpy="-1.5707 0 1.5707" xyz="0.143 0 -0.0088"/>
    <axis xyz="0 0 0"/>
    <parent link="upper_jaw"/>
    <child link="air_feed_plate"/>
  </joint>
  <joint name="joint_upper_vacuum" type="fixed">
    <origin rpy="0 -1.5707 0.0" xyz="-0.038 0.006 0.2943"/>
    <axis xyz="0 0 0"/>
    <parent link="base_uni"/>
    <child link="upper_vacuum"/>
  </joint>
  <joint name="joint_sponge_upper_jaw" type="fixed">
    <origin rpy="0 0 0" xyz="-0.081 0 0.0165"/>
    <axis xyz="0 0 0"/>
    <parent link="upper_jaw"/>
    <child link="sponge_upper_jaw"/>
  </joint>
  <joint name="joint_vacuum_base" type="fixed">
    <origin rpy="0 0 0" xyz="-0.1495 0 0"/>
    <axis xyz="0 0 0"/>
    <parent link="upper_jaw"/>
    <child link="vacuum_base"/>
  </joint>
  <joint name="joint_pre_front_vacuum" type="fixed">
    <origin rpy="0 1.5707 0" xyz="-0.0275 0 0"/>
    <axis xyz="0 0 0"/>
    <parent link="vacuum_base"/>
    <child link="pre_front_vacuum"/>
  </joint>
  <joint name="joint_front_vacuum" type="fixed">
    <origin rpy="0 0 0" xyz="-0.019 0.005 0.4068"/>
    <axis xyz="0 0 0"/>
    <parent link="base_uni"/>
    <child link="front_vacuum"/>
  </joint>
  <!-- link list -->
  <link name="base_link">
    <visual>
      <geometry>
        <mesh filename="package://motoman_sda10f_support/meshes/sda10f/visual/motoman_base.stl"/>
      </geometry>
      <material name="blue">
        <color rgba="0 0 1 1"/>
      </material>
    </visual>
    <collision>
      <geometry>
        <mesh filename="package://motoman_sda10f_support/meshes/sda10f/collision/motoman_base.stl"/>
      </geometry>
      <material name="yellow">
        <color rgba="0 1 1 1"/>
      </material>
    </collision>
    <inertial>
      <mass value="0.00001"/>
      <origin rpy="0 -0 0" xyz="0 0 0"/>
      <inertia ixx="1" ixy="0" ixz="0" iyy="1" iyz="0" izz="1"/>
    </inertial>
  </link>
  <link name="torso_link_b1">
    <visual>
      <origin rpy="0 0 0" xyz="0 0 0"/>
      <geometry>
        <mesh filename="package://motoman_sda10f_support/meshes/sda10f/visual/motoman_axis_b1.stl"/>
      </geometry>
      <material name="silver">
        <color rgba="0.8 0.8 0.8 1"/>
      </material>
    </visual>
    <collision>
      <origin rpy="0 0 0" xyz="0 0 0"/>
      <geometry>
        <mesh filename="package://motoman_sda10f_support/meshes/sda10f/collision/motoman_axis_b1.stl"/>
      </geometry>
      <material name="yellow"/>
    </collision>
  </link>
  <link name="torso_link_b2">
    <visual>
      <origin rpy="0 0 0" xyz="0 0 0"/>
      <geometry>
        <mesh filename="package://motoman_sda10f_support/meshes/sda10f/visual/motoman_axis_b1.stl"/>
      </geometry>
      <material name="silver">
        <color rgba="0.8 0.8 0.8 1"/>
      </material>
    </visual>
    <collision>
      <origin rpy="0 0 0" xyz="0 0 0"/>
      <geometry>
        <mesh filename="package://motoman_sda10f_support/meshes/sda10f/collision/motoman_axis_b1.stl"/>
      </geometry>
      <material name="yellow"/>
    </collision>
  </link>
  <!-- joint list -->
  <joint name="torso_joint_b1" type="revolute">
    <parent link="base_link"/>
    <child link="torso_link_b1"/>
    <origin rpy="0 0 0" xyz="0.09257 0 0.877"/>
    <axis xyz="0 0 1"/>
    <limit effort="100" lower="-2.9570" upper="2.9570" velocity="2.26"/>
  </joint>
  <joint name="torso_joint_b2" type="revolute">
    <parent link="base_link"/>
    <child link="torso_link_b2"/>
    <origin rpy="0 0 0" xyz="0.09257 0 0.8835"/>
    <axis xyz="0 0 1"/>
    <limit effort="100" lower="-2.9570" upper="2.9570" velocity="2.26"/>
    <!-- <mimic joint="${prefix}joint_b1" multiplier="1" offset="0"/>-->
  </joint>
  <!-- end of joint list -->
  <link name="arm_left_link_1_s">
    <visual>
      <origin rpy="0 0 0" xyz="0 0 0"/>
      <geometry>
        <mesh filename="package://motoman_sda10f_support/meshes/sda10f/visual/motoman_axis_s.stl"/>
      </geometry>
      <material name="blue">
        <color rgba="0.65 0.65 0.65 1"/>
      </material>
    </visual>
    <collision>
      <origin rpy="0 0 0" xyz="0 0 0"/>
      <geometry>
        <mesh filename="package://motoman_sda10f_support/meshes/sda10f/collision/motoman_axis_s.stl"/>
      </geometry>
      <material name="yellow"/>
    </collision>
  </link>
  <link name="arm_left_link_2_l">
    <visual>
      <origin rpy="0 0 0" xyz="0 0 0"/>
      <geometry>
        <mesh filename="package://motoman_sda10f_support/meshes/sda10f/visual/motoman_axis_l.stl"/>
      </geometry>
      <material name="silver"/>
    </visual>
    <collision>
      <origin rpy="0 0 0" xyz="0 0 0"/>
      <geometry>
        <mesh filename="package://motoman_sda10f_support/meshes/sda10f/collision/motoman_axis_l.stl"/>
      </geometry>
      <material name="yellow"/>
    </collision>
  </link>
  <link name="arm_left_link_3_e">
    <visual>
      <origin rpy="0 0 0" xyz="0 0 0"/>
      <geometry>
        <mesh filename="package://motoman_sda10f_support/meshes/sda10f/visual/motoman_axis_e.stl"/>
      </geometry>
      <material name="blue"/>
    </visual>
    <collision>
      <origin rpy="0 0 0" xyz="0 0 0"/>
      <geometry>
        <mesh filename="package://motoman_sda10f_support/meshes/sda10f/collision/motoman_axis_e.stl"/>
      </geometry>
      <material name="yellow"/>
    </collision>
  </link>
  <link name="arm_left_link_4_u">
    <visual>
      <origin rpy="0 0 0" xyz="0 0 0"/>
      <geometry>
        <mesh filename="package://motoman_sda10f_support/meshes/sda10f/visual/motoman_axis_u.stl"/>
      </geometry>
      <material name="silver"/>
    </visual>
    <collision>
      <origin rpy="0 0 0" xyz="0 0 0"/>
      <geometry>
        <mesh filename="package://motoman_sda10f_support/meshes/sda10f/collision/motoman_axis_u.stl"/>
      </geometry>
      <material name="yellow"/>
    </collision>
  </link>
  <link name="arm_left_link_5_r">
    <visual>
      <origin rpy="0 0 0" xyz="0 0 0"/>
      <geometry>
        <mesh filename="package://motoman_sda10f_support/meshes/sda10f/visual/motoman_axis_r.stl"/>
      </geometry>
      <material name="blue"/>
    </visual>
    <collision>
      <origin rpy="0 0 0" xyz="0 0 0"/>
      <geometry>
        <mesh filename="package://motoman_sda10f_support/meshes/sda10f/collision/motoman_axis_r.stl"/>
      </geometry>
      <material name="yellow"/>
    </collision>
  </link>
  <link name="arm_left_link_6_b">
    <visual>
      <origin rpy="0 0 0" xyz="0 0 0"/>
      <geometry>
        <mesh filename="package://motoman_sda10f_support/meshes/sda10f/visual/motoman_axis_b.stl"/>
      </geometry>
      <material name="silver"/>
    </visual>
    <collision>
      <origin rpy="0 0 0" xyz="0 0 0"/>
      <geometry>
        <mesh filename="package://motoman_sda10f_support/meshes/sda10f/collision/motoman_axis_b.stl"/>
      </geometry>
      <material name="yellow"/>
    </collision>
  </link>
  <link name="arm_left_link_7_t">
    <visual>
      <geometry>
        <mesh filename="package://motoman_sda10f_support/meshes/sda10f/visual/motoman_axis_t.stl"/>
      </geometry>
      <material name="blue"/>
    </visual>
    <collision>
      <geometry>
        <mesh filename="package://motoman_sda10f_support/meshes/sda10f/collision/motoman_axis_t.stl"/>
      </geometry>
      <material name="yellow"/>
    </collision>
  </link>
  <link name="arm_left_link_tool0"/>
  <joint name="arm_left_joint_1_s" type="revolute">
    <parent link="torso_link_b1"/>
    <child link="arm_left_link_1_s"/>
    <origin rpy="1.57 0 0.0" xyz="0.09996 0.0375 0.32214"/>
    <axis xyz="0 0 -1.0"/>
    <limit effort="0" lower="-3.13" upper="3.13" velocity="2.95"/>
  </joint>
  <joint name="arm_left_joint_2_l" type="revolute">
    <parent link="arm_left_link_1_s"/>
    <child link="arm_left_link_2_l"/>
    <origin rpy="-1.57 0 0" xyz="0 0.0427 -0.2255"/>
    <axis xyz="0 0 -1.0"/>
    <limit effort="0" lower="-1.90" upper="1.90" velocity="2.95"/>
  </joint>
  <joint name="arm_left_joint_3_e" type="revolute">
    <parent link="arm_left_link_2_l"/>
    <child link="arm_left_link_3_e"/>
    <origin rpy="1.57 0 0" xyz="0 0.1790 -0.0454"/>
    <axis xyz="0 0 -1.0"/>
    <limit effort="0" lower="-2.95" upper="2.95" velocity="2.95"/>
  </joint>
  <joint name="arm_left_joint_4_u" type="revolute">
    <parent link="arm_left_link_3_e"/>
    <child link="arm_left_link_4_u"/>
    <origin rpy="-1.57 0 0" xyz="0 -0.0175 -0.181"/>
    <axis xyz="0 0 1"/>
    <limit effort="0" lower="-2.36" upper="2.36" velocity="2.95"/>
  </joint>
  <joint name="arm_left_joint_5_r" type="revolute">
    <parent link="arm_left_link_4_u"/>
    <child link="arm_left_link_5_r"/>
    <origin rpy="1.57 0 0" xyz="0 0.2036 0.0155"/>
    <axis xyz="0 0 1"/>
    <limit effort="0" lower="-3.13" upper="3.13" velocity="3.48"/>
  </joint>
  <joint name="arm_left_joint_6_b" type="revolute">
    <parent link="arm_left_link_5_r"/>
    <child link="arm_left_link_6_b"/>
    <origin rpy="-1.57 0 0" xyz="0 0.0130 -0.155"/>
    <axis xyz="0 0 1"/>
    <limit effort="0" lower="-1.90" upper="1.90" velocity="3.48"/>
  </joint>
  <joint name="arm_left_joint_7_t" type="revolute">
    <parent link="arm_left_link_6_b"/>
    <child link="arm_left_link_7_t"/>
    <origin rpy="1.57 0 0" xyz="0 0.144 -0.015"/>
    <axis xyz="0 0 1"/>
    <limit effort="0" lower="-3.13" upper="3.13" velocity="6.97"/>
  </joint>
  <joint name="arm_left_joint_tool0" type="fixed">
    <origin rpy="0 0 -3.13" xyz="0 0 0.0"/>
    <parent link="arm_left_link_7_t"/>
    <child link="arm_left_link_tool0"/>
  </joint>
  <!-- end of joint list -->
  <link name="arm_right_link_1_s">
    <visual>
      <origin rpy="0 0 0" xyz="0 0 0"/>
      <geometry>
        <mesh filename="package://motoman_sda10f_support/meshes/sda10f/visual/motoman_axis_s.stl"/>
      </geometry>
      <material name="blue">
        <color rgba="0.65 0.65 0.65 1"/>
      </material>
    </visual>
    <collision>
      <origin rpy="0 0 0" xyz="0 0 0"/>
      <geometry>
        <mesh filename="package://motoman_sda10f_support/meshes/sda10f/collision/motoman_axis_s.stl"/>
      </geometry>
      <material name="yellow"/>
    </collision>
  </link>
  <link name="arm_right_link_2_l">
    <visual>
      <origin rpy="0 0 0" xyz="0 0 0"/>
      <geometry>
        <mesh filename="package://motoman_sda10f_support/meshes/sda10f/visual/motoman_axis_l.stl"/>
      </geometry>
      <material name="silver"/>
    </visual>
    <collision>
      <origin rpy="0 0 0" xyz="0 0 0"/>
      <geometry>
        <mesh filename="package://motoman_sda10f_support/meshes/sda10f/collision/motoman_axis_l.stl"/>
      </geometry>
      <material name="yellow"/>
    </collision>
  </link>
  <link name="arm_right_link_3_e">
    <visual>
      <origin rpy="0 0 0" xyz="0 0 0"/>
      <geometry>
        <mesh filename="package://motoman_sda10f_support/meshes/sda10f/visual/motoman_axis_e.stl"/>
      </geometry>
      <material name="blue"/>
    </visual>
    <collision>
      <origin rpy="0 0 0" xyz="0 0 0"/>
      <geometry>
        <mesh filename="package://motoman_sda10f_support/meshes/sda10f/collision/motoman_axis_e.stl"/>
      </geometry>
      <material name="yellow"/>
    </collision>
  </link>
  <link name="arm_right_link_4_u">
    <visual>
      <origin rpy="0 0 0" xyz="0 0 0"/>
      <geometry>
        <mesh filename="package://motoman_sda10f_support/meshes/sda10f/visual/motoman_axis_u.stl"/>
      </geometry>
      <material name="silver"/>
    </visual>
    <collision>
      <origin rpy="0 0 0" xyz="0 0 0"/>
      <geometry>
        <mesh filename="package://motoman_sda10f_support/meshes/sda10f/collision/motoman_axis_u.stl"/>
      </geometry>
      <material name="yellow"/>
    </collision>
  </link>
  <link name="arm_right_link_5_r">
    <visual>
      <origin rpy="0 0 0" xyz="0 0 0"/>
      <geometry>
        <mesh filename="package://motoman_sda10f_support/meshes/sda10f/visual/motoman_axis_r.stl"/>
      </geometry>
      <material name="blue"/>
    </visual>
    <collision>
      <origin rpy="0 0 0" xyz="0 0 0"/>
      <geometry>
        <mesh filename="package://motoman_sda10f_support/meshes/sda10f/collision/motoman_axis_r.stl"/>
      </geometry>
      <material name="yellow"/>
    </collision>
  </link>
  <link name="arm_right_link_6_b">
    <visual>
      <origin rpy="0 0 0" xyz="0 0 0"/>
      <geometry>
        <mesh filename="package://motoman_sda10f_support/meshes/sda10f/visual/motoman_axis_b.stl"/>
      </geometry>
      <material name="silver"/>
    </visual>
    <collision>
      <origin rpy="0 0 0" xyz="0 0 0"/>
      <geometry>
        <mesh filename="package://motoman_sda10f_support/meshes/sda10f/collision/motoman_axis_b.stl"/>
      </geometry>
      <material name="yellow"/>
    </collision>
  </link>
  <link name="arm_right_link_7_t">
    <visual>
      <geometry>
        <mesh filename="package://motoman_sda10f_support/meshes/sda10f/visual/motoman_axis_t.stl"/>
      </geometry>
      <material name="blue"/>
    </visual>
    <collision>
      <geometry>
        <mesh filename="package://motoman_sda10f_support/meshes/sda10f/collision/motoman_axis_t.stl"/>
      </geometry>
      <material name="yellow"/>
    </collision>
  </link>
  <link name="arm_right_link_tool0"/>
  <joint name="arm_right_joint_1_s" type="revolute">
    <parent link="torso_link_b1"/>
    <child link="arm_right_link_1_s"/>
    <origin rpy="1.57 0 -3.14" xyz="0.09996 -0.0375 0.32214"/>
    <axis xyz="0 0 1.0"/>
    <limit effort="0" lower="-3.13" upper="3.13" velocity="2.95"/>
  </joint>
  <joint name="arm_right_joint_2_l" type="revolute">
    <parent link="arm_right_link_1_s"/>
    <child link="arm_right_link_2_l"/>
    <origin rpy="-1.57 0 0" xyz="0 0.0427 -0.2255"/>
    <axis xyz="0 0 1.0"/>
    <limit effort="0" lower="-1.90" upper="1.90" velocity="2.95"/>
  </joint>
  <joint name="arm_right_joint_3_e" type="revolute">
    <parent link="arm_right_link_2_l"/>
    <child link="arm_right_link_3_e"/>
    <origin rpy="1.57 0 0" xyz="0 0.1790 -0.0454"/>
    <axis xyz="0 0 1.0"/>
    <limit effort="0" lower="-2.95" upper="2.95" velocity="2.95"/>
  </joint>
  <joint name="arm_right_joint_4_u" type="revolute">
    <parent link="arm_right_link_3_e"/>
    <child link="arm_right_link_4_u"/>
    <origin rpy="-1.57 0 0" xyz="0 -0.0175 -0.181"/>
    <axis xyz="0 0 -1"/>
    <limit effort="0" lower="-2.36" upper="2.36" velocity="2.95"/>
  </joint>
  <joint name="arm_right_joint_5_r" type="revolute">
    <parent link="arm_right_link_4_u"/>
    <child link="arm_right_link_5_r"/>
    <origin rpy="1.57 0 0" xyz="0 0.2036 0.0155"/>
    <axis xyz="0 0 -1"/>
    <limit effort="0" lower="-3.13" upper="3.13" velocity="3.48"/>
  </joint>
  <joint name="arm_right_joint_6_b" type="revolute">
    <parent link="arm_right_link_5_r"/>
    <child link="arm_right_link_6_b"/>
    <origin rpy="-1.57 0 0" xyz="0 0.0130 -0.155"/>
    <axis xyz="0 0 -1"/>
    <limit effort="0" lower="-1.90" upper="1.90" velocity="3.48"/>
  </joint>
  <joint name="arm_right_joint_7_t" type="revolute">
    <parent link="arm_right_link_6_b"/>
    <child link="arm_right_link_7_t"/>
    <origin rpy="1.57 0 0" xyz="0 0.144 -0.015"/>
    <axis xyz="0 0 -1"/>
    <limit effort="0" lower="-3.13" upper="3.13" velocity="6.97"/>
  </joint>
  <joint name="arm_right_joint_tool0" type="fixed">
    <origin rpy="0 0 -3.13" xyz="0 0 0.0"/>
    <parent link="arm_right_link_7_t"/>
    <child link="arm_right_link_tool0"/>
  </joint>
  <!-- end of joint list -->
  <joint name="robot-hand" type="fixed">
    <origin rpy="3.14159 0.0 3.14159" xyz="0 0 -0.056"/>
    <parent link="arm_right_link_tool0"/>
    <child link="base_uni"/>
  </joint>
  <xacro:reflex_model prefix="unigripper_ps">
        </xacro:reflex_model>
  <joint name="unigripper_joint" type="fixed">
    <origin rpy="0 3.1415 -1.57" xyz="0 0 -0.015"/>
    <parent link="arm_left_link_tool0"/>
    <child link="base_plate"/>
  </joint>
  <link name="base_plate">
    <visual>
      <geometry>
        <cylinder length="0.008" radius="0.04"/>
      </geometry>
      <material name="silver">
        <color rgba="0.76 0.76 0.82 1"/>
      </material>
    </visual>
    <collision>
      <origin rpy="0 0 0" xyz="0 0 0"/>
      <geometry>
        <cylinder length="0.008" radius="0.04"/>
      </geometry>
      <material name="silver">
        <color rgba="0.76 0.76 0.82 1"/>
      </material>
    </collision>
    <inertial>
      <origin rpy="0 0 0" xyz="0 0 0"/>
      <mass value="0.002"/>
      <inertia ixx="0" ixy="0" ixz="0" iyy="0" iyz="0" izz="0"/>
    </inertial>
  </link>
  <link name="main_beam">
    <visual>
      <geometry>
        <box size="0.015 0.040 0.180"/>
      </geometry>
      <material name="silver">
        <color rgba="0.76 0.76 0.82 1"/>
      </material>
    </visual>
    <collision>
      <origin rpy="0 0 0" xyz="0 0 0.0"/>
      <geometry>
        <box size="0.015 0.040 0.180"/>
      </geometry>
      <material name="silver">
        <color rgba="0.76 0.76 0.82 1"/>
      </material>
    </collision>
    <inertial>
      <origin rpy="0 0 0" xyz="0 0 0"/>
      <mass value="0.01"/>
      <inertia ixx="0" ixy="0" ixz="0" iyy="0" iyz="0" izz="0"/>
    </inertial>
  </link>
  <link name="actuator">
    <visual>
      <geometry>
        <box size="0.03 0.035 0.180"/>
      </geometry>
      <material name="dark_grey">
        <color rgba="0.2 0.2 0.2 1"/>
      </material>
    </visual>
    <collision>
      <origin rpy="0 0 0" xyz="0 0 0.0"/>
      <geometry>
        <box size="0.03 0.035 0.180"/>
      </geometry>
      <material name="dark_grey">
        <color rgba="0.2 0.2 0.2 1"/>
      </material>
    </collision>
    <inertial>
      <origin rpy="0 0 0" xyz="0 0 0"/>
      <mass value="0.01"/>
      <inertia ixx="0" ixy="0" ixz="0" iyy="0" iyz="0" izz="0"/>
    </inertial>
  </link>
  <link name="head_connector">
    <visual>
      <origin rpy="0 0 0" xyz="-0.01 0.0 -0.004"/>
      <geometry>
        <box size="0.035 0.015 0.039"/>
      </geometry>
      <material name="silver">
        <color rgba="0.76 0.76 0.82 1"/>
      </material>
    </visual>
    <collision>
      <origin rpy="0 0 0" xyz="-0.01 0.0 -0.004"/>
      <geometry>
        <box size="0.035 0.015 0.039"/>
      </geometry>
      <material name="silver">
        <color rgba="0.76 0.76 0.82 1"/>
      </material>
    </collision>
    <inertial>
      <origin rpy="0 0 0" xyz="0 0 0"/>
      <mass value="0.01"/>
      <inertia ixx="0" ixy="0" ixz="0" iyy="0" iyz="0" izz="0"/>
    </inertial>
  </link>
  <link name="head_plate">
    <visual>
      <origin rpy="0 0 0" xyz="-0.01 0.0 -0.004"/>
      <geometry>
        <box size="0.045 0.045 0.005"/>
      </geometry>
      <material name="silver">
        <color rgba="0.76 0.76 0.82 1"/>
      </material>
    </visual>
    <collision>
      <origin rpy="0 0 0" xyz="-0.01 0.0 -0.004"/>
      <geometry>
        <box size="0.045 0.045 0.005"/>
      </geometry>
      <material name="silver">
        <color rgba="0.76 0.76 0.82 1"/>
      </material>
    </collision>
    <inertial>
      <origin rpy="0 0 0" xyz="0 0 0"/>
      <mass value="0.01"/>
      <inertia ixx="0" ixy="0" ixz="0" iyy="0" iyz="0" izz="0"/>
    </inertial>
  </link>
  <link name="head_base">
    <visual>
      <geometry>
        <mesh filename="package://motoman_sda10f_support/meshes/sda10f/visual/grippy.stl"/>
      </geometry>
      <material name="red">
        <color rgba="1 0 0 1"/>
      </material>
    </visual>
    <collision>
      <origin rpy="0 0 0" xyz="0 0 0"/>
      <geometry>
        <mesh filename="package://motoman_sda10f_support/meshes/sda10f/visual/grippy.stl"/>
      </geometry>
      <material name="red">
        <color rgba="1 0 0 1"/>
      </material>
    </collision>
    <inertial>
      <origin rpy="0 0 0" xyz="0 0 0"/>
      <mass value="0.0"/>
      <inertia ixx="0" ixy="0" ixz="0" iyy="0" iyz="0" izz="0"/>
    </inertial>
  </link>
  <link name="pre_suction_cup_left">
    <visual>
      <origin rpy="0 0 0" xyz="0 0 0"/>
      <geometry>
        <cylinder length="0.03" radius="0.01"/>
      </geometry>
      <material name="green">
        <color rgba="0 1 0 1"/>
      </material>
    </visual>
    <collision>
      <origin rpy="0 0 0" xyz="0 0 0"/>
      <geometry>
        <cylinder length="0.03" radius="0.01"/>
      </geometry>
      <material name="green">
        <color rgba="0 1 0 1"/>
      </material>
    </collision>
    <inertial>
      <origin rpy="0 0 0" xyz="0 0 0"/>
      <mass value="0.01"/>
      <inertia ixx="0" ixy="0" ixz="0" iyy="0" iyz="0" izz="0"/>
    </inertial>
  </link>
  <link name="pre_suction_cup_right">
    <visual>
      <origin rpy="0 0 0" xyz="0 0 0"/>
      <geometry>
        <cylinder length="0.03" radius="0.01"/>
      </geometry>
      <material name="green">
        <color rgba="0 1 0 1"/>
      </material>
    </visual>
    <collision>
      <origin rpy="0 0 0" xyz="0 0 0"/>
      <geometry>
        <cylinder length="0.03" radius="0.01"/>
      </geometry>
      <material name="green">
        <color rgba="0 1 0 1"/>
      </material>
    </collision>
    <inertial>
      <origin rpy="0 0 0" xyz="0 0 0"/>
      <mass value="0.01"/>
      <inertia ixx="0" ixy="0" ixz="0" iyy="0" iyz="0" izz="0"/>
    </inertial>
  </link>
  <link name="suction_cup_left">
    <visual>
      <origin rpy="0 0 0" xyz="0 0 0"/>
      <geometry>
        <cylinder length="0.005" radius="0.0175"/>
      </geometry>
      <material name="green">
        <color rgba="0 1 0 1"/>
      </material>
    </visual>
    <collision>
      <origin rpy="0 0 0" xyz="0 0 0"/>
      <geometry>
        <cylinder length="0.005" radius="0.0175"/>
      </geometry>
      <material name="green">
        <color rgba="0 1 0 1"/>
      </material>
    </collision>
    <inertial>
      <origin rpy="0 0 0" xyz="0 0 0"/>
      <mass value="0.01"/>
      <inertia ixx="0" ixy="0" ixz="0" iyy="0" iyz="0" izz="0"/>
    </inertial>
  </link>
  <link name="suction_cup_right">
    <visual>
      <origin rpy="0 0 0" xyz="0 0 0"/>
      <geometry>
        <cylinder length="0.005" radius="0.0175"/>
      </geometry>
      <material name="green">
        <color rgba="0 1 0 1"/>
      </material>
    </visual>
    <collision>
      <origin rpy="0 0 0" xyz="0 0 0"/>
      <geometry>
        <cylinder length="0.005" radius="0.0175"/>
      </geometry>
      <material name="green">
        <color rgba="0 1 0 1"/>
      </material>
    </collision>
    <inertial>
      <origin rpy="0 0 0" xyz="0 0 0"/>
      <mass value="0.01"/>
      <inertia ixx="0" ixy="0" ixz="0" iyy="0" iyz="0" izz="0"/>
    </inertial>
  </link>
  <link name="tube_port">
    <visual>
      <origin rpy="0 0 0" xyz="0 0 0"/>
      <geometry>
        <cylinder length="0.023" radius="0.01"/>
      </geometry>
      <material name="blue">
        <color rgba="0.1 0.1 0.92 1"/>
      </material>
    </visual>
    <collision>
      <origin rpy="0 0 0" xyz="0 0 0"/>
      <geometry>
        <cylinder length="0.023" radius="0.01"/>
      </geometry>
      <material name="blue">
        <color rgba="0.1 0.1 0.92 1"/>
      </material>
    </collision>
    <inertial>
      <origin rpy="0 0 0" xyz="0 0 0"/>
      <mass value="0.01"/>
      <inertia ixx="0" ixy="0" ixz="0" iyy="0" iyz="0" izz="0"/>
    </inertial>
  </link>
  <link name="head_sponge">
    <visual>
      <origin rpy="0 0 0" xyz="0 0 0"/>
      <geometry>
        <box size="0.07 0.03 0.005"/>
      </geometry>
      <material name="blue">
        <color rgba="0 0 1 1"/>
      </material>
    </visual>
    <collision>
      <origin rpy="0 0 0" xyz="0 0 0"/>
      <geometry>
        <box size="0.07 0.03 0.005"/>
      </geometry>
      <material name="blue">
        <color rgba="0 0 1 1"/>
      </material>
    </collision>
    <inertial>
      <origin rpy="0 0 0" xyz="0 0 0"/>
      <mass value="0.01"/>
      <inertia ixx="0" ixy="0" ixz="0" iyy="0" iyz="0" izz="0"/>
    </inertial>
  </link>
  <!-- Joints -->
  <joint name="plate_beam" type="fixed">
    <origin rpy="0 0 0" xyz="0.0 0.0 0.094"/>
    <axis xyz="0 0 0"/>
    <parent link="base_plate"/>
    <child link="main_beam"/>
  </joint>
  <joint name="beam_act" type="fixed">
    <origin rpy="0 0 0" xyz="-0.0225 0.0 0.0"/>
    <axis xyz="0 0 0"/>
    <parent link="main_beam"/>
    <child link="actuator"/>
  </joint>
  <joint name="neck_plate" type="fixed">
    <origin rpy="0 0 0" xyz="0.0 0 0.022"/>
    <axis xyz="0 0 0"/>
    <parent link="head_connector"/>
    <child link="head_plate"/>
  </joint>
  <joint name="joint_base_head" type="fixed">
    <origin rpy="0 0 1.5707" xyz="-0.0095 0.0002 0.0053"/>
    <axis xyz="0 0 0"/>
    <parent link="head_plate"/>
    <child link="head_base"/>
  </joint>
  <joint name="joint_suction_cup_right" type="fixed">
    <origin rpy="0 0 0" xyz="0 0 0.0175"/>
    <axis xyz="0 0 0"/>
    <parent link="pre_suction_cup_right"/>
    <child link="suction_cup_right"/>
  </joint>
  <joint name="joint_suction_cup_left" type="fixed">
    <origin rpy="0 0 0" xyz="0 0 0.0175"/>
    <axis xyz="0 0 0"/>
    <parent link="pre_suction_cup_left"/>
    <child link="suction_cup_left"/>
  </joint>
  <joint name="joint_pre_suction_cup_right" type="fixed">
    <origin rpy="0 0 0" xyz="-0.02 0.0002 0.0273"/>
    <axis xyz="0 0 0"/>
    <parent link="head_base"/>
    <child link="pre_suction_cup_right"/>
  </joint>
  <joint name="joint_pre_suction_cup_left" type="fixed">
    <origin rpy="0 0 0" xyz="0.02 0.0002 0.0273"/>
    <axis xyz="0 0 0"/>
    <parent link="head_base"/>
    <child link="pre_suction_cup_left"/>
  </joint>
  <joint name="head_valve" type="fixed">
    <origin rpy="0 0 0" xyz="0.033 0 -0.021"/>
    <axis xyz="0 0 0"/>
    <parent link="head_base"/>
    <child link="tube_port"/>
  </joint>
  <joint name="joint_head_sponge" type="fixed">
    <origin rpy="0 0 0" xyz="0 0 0.0498"/>
    <axis xyz="0 0 0"/>
    <parent link="head_base"/>
    <child link="head_sponge"/>
  </joint>
  <joint name="head_hinge" type="revolute">
    <origin rpy="0 0 0" xyz="0.0 0.0 0.0825"/>
    <axis xyz="0 1 0"/>
    <parent link="main_beam"/>
    <child link="head_connector"/>
    <dynamics damping="0.0" friction="0.5"/>
    <limit effort="50" lower="0.0" upper="1.57" velocity="0.2"/>
  </joint>
  <joint name="left_kinect_joint" type="fixed">
    <origin rpy="3.1416 0 0" xyz="0.0 0.006 0.047"/>
    <parent link="arm_left_link_6_b"/>
    <child link="left_kinect_base_1"/>
  </joint>
  <link name="left_kinect_base_1">
    <visual>
      <geometry>
        <mesh filename="package://motoman_sda10f_support/meshes/sda10f/visual/kinect_base_1.stl"/>
      </geometry>
      <material name="red">
        <color rgba="1 0 0 1"/>
      </material>
    </visual>
    <collision>
      <origin rpy="0 0 0" xyz="0 0 0"/>
      <geometry>
        <mesh filename="package://motoman_sda10f_support/meshes/sda10f/visual/kinect_base_1.stl"/>
      </geometry>
      <material name="red">
        <color rgba="1 0 0 1"/>
      </material>
    </collision>
  </link>
  <link name="left_kinect_base_2">
    <visual>
      <geometry>
        <mesh filename="package://motoman_sda10f_support/meshes/sda10f/visual/kinect_base_2.stl"/>
      </geometry>
      <material name="red">
        <color rgba="1 0 0 1"/>
      </material>
    </visual>
    <collision>
      <origin rpy="0 0 0" xyz="0 0 0"/>
      <geometry>
        <mesh filename="package://motoman_sda10f_support/meshes/sda10f/visual/kinect_base_2.stl"/>
      </geometry>
      <material name="red">
        <color rgba="1 0 0 1"/>
      </material>
    </collision>
  </link>
  <link name="left_kinect_head">
    <visual>
      <origin rpy="0 0 0" xyz="0.0 0.0 0.0"/>
      <geometry>
        <box size="0.066 0.25 0.043"/>
      </geometry>
      <material name="black">
        <color rgba="0.05 0.05 0.05 1"/>
      </material>
    </visual>
    <collision>
      <origin rpy="0 0 0" xyz="0.0 0.0 0.0"/>
      <geometry>
        <box size="0.068 0.252 0.045"/>
      </geometry>
      <material name="black">
        <color rgba="0.05 0.05 0.05 1"/>
      </material>
    </collision>
  </link>
  <link name="left_RGB_camera">
    <visual>
      <origin rpy="0 0 0" xyz="0.0 0.0 0.0"/>
      <geometry>
        <cylinder length="0.011" radius="0.0145"/>
      </geometry>
      <material name="blackish">
        <color rgba="0.09 0.09 0.09 1"/>
      </material>
    </visual>
    <collision>
      <origin rpy="0 0 0" xyz="0.0 0.0 0.0"/>
      <geometry>
        <cylinder length="0.011" radius="0.0145"/>
      </geometry>
      <material name="blackish">
        <color rgba="0.09 0.09 0.09 1"/>
      </material>
    </collision>
  </link>
  <link name="left_IR_camera">
    <visual>
      <origin rpy="0 0 0" xyz="0.0 0.0 0.0"/>
      <geometry>
        <cylinder length="0.011" radius="0.009"/>
      </geometry>
      <material name="blackgreen">
        <color rgba="0.09 0.29 0.09 1"/>
      </material>
    </visual>
    <collision>
      <origin rpy="0 0 0" xyz="0.0 0.0 0.0"/>
      <geometry>
        <cylinder length="0.011" radius="0.009"/>
      </geometry>
      <material name="blackgreen">
        <color rgba="0.09 0.29 0.09 1"/>
      </material>
    </collision>
  </link>
  <!-- Joints -->
  <joint name="left_kinect_bases" type="fixed">
    <origin rpy="3.1416 0 1.5708" xyz="0 0 -0.023"/>
    <axis xyz="0 0 0"/>
    <parent link="left_kinect_base_1"/>
    <child link="left_kinect_base_2"/>
  </joint>
  <joint name="left_kinect_hinge" type="fixed">
    <origin rpy="0 0 -1.5708" xyz="0 0 0.027"/>
    <axis xyz="0 0 0"/>
    <parent link="left_kinect_base_2"/>
    <child link="left_kinect_head"/>
  </joint>
  <joint name="left_fixed_rgb" type="fixed">
    <origin rpy="1.5708 3.1416 1.5708" xyz="0.0275 -0.0965 0.0"/>
    <axis xyz="0 0 0"/>
    <parent link="left_kinect_head"/>
    <child link="left_RGB_camera"/>
  </joint>
  <joint name="left_fixed_ir" type="fixed">
    <origin rpy="1.5708 3.1416 1.5708" xyz="0.0275 0.086 0.0"/>
    <axis xyz="0 0 0"/>
    <parent link="left_kinect_head"/>
    <child link="left_IR_camera"/>
  </joint>
  <joint name="right_kinect_joint" type="fixed">
    <origin rpy="3.1416 0 0" xyz="0.0 0.006 0.047"/>
    <parent link="arm_right_link_6_b"/>
    <child link="right_kinect_base_1"/>
  </joint>
  <link name="right_kinect_base_1">
    <visual>
      <geometry>
        <mesh filename="package://motoman_sda10f_support/meshes/sda10f/visual/kinect_base_1.stl"/>
      </geometry>
      <material name="red">
        <color rgba="1 0 0 1"/>
      </material>
    </visual>
    <collision>
      <origin rpy="0 0 0" xyz="0 0 0"/>
      <geometry>
        <mesh filename="package://motoman_sda10f_support/meshes/sda10f/visual/kinect_base_1.stl"/>
      </geometry>
      <material name="red">
        <color rgba="1 0 0 1"/>
      </material>
    </collision>
  </link>
  <link name="right_kinect_base_2">
    <visual>
      <geometry>
        <mesh filename="package://motoman_sda10f_support/meshes/sda10f/visual/kinect_base_2.stl"/>
      </geometry>
      <material name="red">
        <color rgba="1 0 0 1"/>
      </material>
    </visual>
    <collision>
      <origin rpy="0 0 0" xyz="0 0 0"/>
      <geometry>
        <mesh filename="package://motoman_sda10f_support/meshes/sda10f/visual/kinect_base_2.stl"/>
      </geometry>
      <material name="red">
        <color rgba="1 0 0 1"/>
      </material>
    </collision>
  </link>
  <link name="right_kinect_head">
    <visual>
      <origin rpy="0 0 0" xyz="0.0 0.0 0.0"/>
      <geometry>
        <box size="0.066 0.25 0.043"/>
      </geometry>
      <material name="black">
        <color rgba="0.05 0.05 0.05 1"/>
      </material>
    </visual>
    <collision>
      <origin rpy="0 0 0" xyz="0.0 0.0 0.0"/>
      <geometry>
        <box size="0.068 0.252 0.045"/>
      </geometry>
      <material name="black">
        <color rgba="0.05 0.05 0.05 1"/>
      </material>
    </collision>
  </link>
  <link name="right_RGB_camera">
    <visual>
      <origin rpy="0 0 0" xyz="0.0 0.0 0.0"/>
      <geometry>
        <cylinder length="0.011" radius="0.0145"/>
      </geometry>
      <material name="blackish">
        <color rgba="0.09 0.09 0.09 1"/>
      </material>
    </visual>
    <collision>
      <origin rpy="0 0 0" xyz="0.0 0.0 0.0"/>
      <geometry>
        <cylinder length="0.011" radius="0.0145"/>
      </geometry>
      <material name="blackish">
        <color rgba="0.09 0.09 0.09 1"/>
      </material>
    </collision>
  </link>
  <link name="right_IR_camera">
    <visual>
      <origin rpy="0 0 0" xyz="0.0 0.0 0.0"/>
      <geometry>
        <cylinder length="0.011" radius="0.009"/>
      </geometry>
      <material name="blackgreen">
        <color rgba="0.09 0.29 0.09 1"/>
      </material>
    </visual>
    <collision>
      <origin rpy="0 0 0" xyz="0.0 0.0 0.0"/>
      <geometry>
        <cylinder length="0.011" radius="0.009"/>
      </geometry>
      <material name="blackgreen">
        <color rgba="0.09 0.29 0.09 1"/>
      </material>
    </collision>
  </link>
  <!-- Joints -->
  <joint name="right_kinect_bases" type="fixed">
    <origin rpy="3.1416 0 1.5708" xyz="0 0 -0.023"/>
    <axis xyz="0 0 0"/>
    <parent link="right_kinect_base_1"/>
    <child link="right_kinect_base_2"/>
  </joint>
  <joint name="right_kinect_hinge" type="fixed">
    <origin rpy="0 0 1.5708" xyz="0 0 0.027"/>
    <axis xyz="0 0 0"/>
    <parent link="right_kinect_base_2"/>
    <child link="right_kinect_head"/>
  </joint>
  <joint name="right_fixed_rgb" type="fixed">
    <origin rpy="1.5708 3.1416 1.5708" xyz="0.0275 -0.0965 0.0"/>
    <axis xyz="0 0 0"/>
    <parent link="right_kinect_head"/>
    <child link="right_RGB_camera"/>
  </joint>
  <joint name="right_fixed_ir" type="fixed">
    <origin rpy="1.5708 3.1416 1.5708" xyz="0.0275 0.086 0.0"/>
    <axis xyz="0 0 0"/>
    <parent link="right_kinect_head"/>
    <child link="right_IR_camera"/>
  </joint>
  <joint name="head_kinect_joint" type="fixed">
    <origin rpy="0 0 0" xyz="0.10695 0.0 0.4772"/>
    <parent link="torso_link_b1"/>
    <child link="head_kinect_base"/>
  </joint>
  <link name="head_kinect_base">
    <visual>
      <origin rpy="0 0 0" xyz="0 0 0"/>
      <geometry>
        <box size="0.076 0.141 0.028"/>
      </geometry>
      <material name="black">
        <color rgba="0.05 0.05 0.05 1"/>
      </material>
    </visual>
    <collision>
      <origin rpy="0 0 0" xyz="0 0 0"/>
      <geometry>
        <box size="0.079 0.144 0.031"/>
      </geometry>
      <material name="black">
        <color rgba="0.05 0.05 0.05 1"/>
      </material>
    </collision>
  </link>
  <link name="head_kinect_head">
    <visual>
      <origin rpy="0 0 0" xyz="0.0 0.0 0.0"/>
      <geometry>
        <box size="0.066 0.25 0.043"/>
      </geometry>
      <material name="black">
        <color rgba="0.05 0.05 0.05 1"/>
      </material>
    </visual>
    <collision>
      <origin rpy="0 0 0" xyz="0.0 0.0 0.0"/>
      <geometry>
        <box size="0.068 0.252 0.045"/>
      </geometry>
      <material name="black">
        <color rgba="0.05 0.05 0.05 1"/>
      </material>
    </collision>
  </link>
  <link name="head_RGB_camera">
    <visual>
      <origin rpy="0 0 0" xyz="0.0 0.0 0.0"/>
      <geometry>
        <cylinder length="0.011" radius="0.0145"/>
      </geometry>
      <material name="blackish">
        <color rgba="0.09 0.09 0.09 1"/>
      </material>
    </visual>
    <collision>
      <origin rpy="0 0 0" xyz="0.0 0.0 0.0"/>
      <geometry>
        <cylinder length="0.011" radius="0.0145"/>
      </geometry>
      <material name="blackish">
        <color rgba="0.09 0.09 0.09 1"/>
      </material>
    </collision>
  </link>
  <link name="head_IR_camera">
    <visual>
      <origin rpy="0 0 0" xyz="0.0 0.0 0.0"/>
      <geometry>
        <cylinder length="0.011" radius="0.009"/>
      </geometry>
      <material name="blackgreen">
        <color rgba="0.09 0.29 0.09 1"/>
      </material>
    </visual>
    <collision>
      <origin rpy="0 0 0" xyz="0.0 0.0 0.0"/>
      <geometry>
        <cylinder length="0.011" radius="0.009"/>
      </geometry>
      <material name="blackgreen">
        <color rgba="0.09 0.29 0.09 1"/>
      </material>
    </collision>
  </link>
  <!-- Joints -->
  <joint name="head_kinect_hinge" type="fixed">
    <origin rpy="0 0 0" xyz="0.006 0.0 0.0325"/>
    <axis xyz="0 0 0"/>
    <parent link="head_kinect_base"/>
    <child link="head_kinect_head"/>
  </joint>
  <joint name="head_fixed_rgb" type="fixed">
    <origin rpy="1.5708 3.1416 1.5708" xyz="0.0275 -0.0965 0.0"/>
    <axis xyz="0 0 0"/>
    <parent link="head_kinect_head"/>
    <child link="head_RGB_camera"/>
  </joint>
  <joint name="head_fixed_ir" type="fixed">
    <origin rpy="1.5708 3.1416 1.5708" xyz="0.0275 0.086 0.0"/>
    <axis xyz="0 0 0"/>
    <parent link="head_kinect_head"/>
    <child link="head_IR_camera"/>
  </joint>
</robot>
